Workbook

Sheet Preisvorschlag
A1: Code | B1: Kategorie | C1: Titel | D1: Details | E1: Status | F1: Preisbasis | G1: Referenzpreis CHF | H1: Breite mm | I1: Höhe mm | J1: Fläche m² | K1: Vorschlag CHF | L1: Entscheid CHF | M1: Rabatt effektiv | N1: Montage h min | O1: Montage h max | P1: Montage CHF min | Q1: Montage CHF max | R1: Link | S1: Bemerkung
A2: GB 01 | B2: Neue Glasplatten | C2: Gebogenes Reliefglas mit Wellenringen | D2: Gebogen · Masse auf Anfrage · 10 mm Glas | E2: verfügbar | F2: Preis auf Anfrage | J2: =IF(OR(H2="",I2=""),"",ROUND(H2*I2/1000000,2)) | K2: =IF(J2="","",ROUND(J2*Annahmen!$B$8/Annahmen!$B$6,0)*Annahmen!$B$6) | M2: =IF(OR(G2="",L2=""),"",1-L2/G2) | N2: 2 | O2: 4 | P2: =N2*Annahmen!$B$9 | Q2: =O2*Annahmen!$B$9 | R2: =HYPERLINK(Annahmen!$B$11&"#artikel/gb-01","Stück öffnen") | S2: Masse fehlen – Preis manuell
A3: GB 02 | B3: Neue Glasplatten | C3: Gebogenes Reliefglas mit Palmenmotiv | D3: Gebogen · Masse auf Anfrage · 10 mm Glas | E3: verfügbar | F3: Preis auf Anfrage | J3: =IF(OR(H3="",I3=""),"",ROUND(H3*I3/1000000,2)) | K3: =IF(J3="","",ROUND(J3*Annahmen!$B$8/Annahmen!$B$6,0)*Annahmen!$B$6) | M3: =IF(OR(G3="",L3=""),"",1-L3/G3) | N3: 2 | O3: 4 | P3: =N3*Annahmen!$B$9 | Q3: =O3*Annahmen!$B$9 | R3: =HYPERLINK(Annahmen!$B$11&"#artikel/gb-02","Stück öffnen") | S3: Masse fehlen – Preis manuell
A4: GB 03 | B4: Neue Glasplatten | C4: Reliefglas mit Zellstruktur und geschwungener Kante | D4: Freie Oberkante · Masse auf Anfrage · 10 mm Glas | E4: verfügbar | F4: Preis auf Anfrage | J4: =IF(OR(H4="",I4=""),"",ROUND(H4*I4/1000000,2)) | K4: =IF(J4="","",ROUND(J4*Annahmen!$B$8/Annahmen!$B$6,0)*Annahmen!$B$6) | M4: =IF(OR(G4="",L4=""),"",1-L4/G4) | N4: 2 | O4: 4 | P4: =N4*Annahmen!$B$9 | Q4: =O4*Annahmen!$B$9 | R4: =HYPERLINK(Annahmen!$B$11&"#artikel/gb-03","Stück öffnen") | S4: Masse fehlen – Preis manuell
A5: GB 04 | B5: Neue Glasplatten | C5: Gebogenes Reliefglas mit Reliefmotiv | D5: Gebogen · Masse auf Anfrage · 10 mm Glas | E5: verfügbar | F5: Preis auf Anfrage | J5: =IF(OR(H5="",I5=""),"",ROUND(H5*I5/1000000,2)) | K5: =IF(J5="","",ROUND(J5*Annahmen!$B$8/Annahmen!$B$6,0)*Annahmen!$B$6) | M5: =IF(OR(G5="",L5=""),"",1-L5/G5) | N5: 2 | O5: 4 | P5: =N5*Annahmen!$B$9 | Q5: =O5*Annahmen!$B$9 | R5: =HYPERLINK(Annahmen!$B$11&"#artikel/gb-04","Stück öffnen") | S5: Masse fehlen – Preis manuell
A6: TW 20 | B6: Neue Glasplatten | C6: Strukturglas-Platte mit grober Textur | D6: 1040 × 1900 mm · 8 mm Glas | E6: verfügbar | F6: Preis auf Anfrage | H6: 1040 | I6: 1900 | J6: =IF(OR(H6="",I6=""),"",ROUND(H6*I6/1000000,2)) | K6: =IF(J6="","",ROUND(J6*Annahmen!$B$7/Annahmen!$B$6,0)*Annahmen!$B$6) | M6: =IF(OR(G6="",L6=""),"",1-L6/G6) | N6: 2 | O6: 4 | P6: =N6*Annahmen!$B$9 | Q6: =O6*Annahmen!$B$9 | R6: =HYPERLINK(Annahmen!$B$11&"#artikel/tw-20","Stück öffnen") | S6: Formel Fläche × CHF/m² (Annahme)
A7: TW 21 | B7: Neue Glasplatten | C7: Strukturglas-Platte mit Tiermotiv | D7: 885 × 1980 mm · 8 mm Glas | E7: verfügbar | F7: Preis auf Anfrage | H7: 885 | I7: 1980 | J7: =IF(OR(H7="",I7=""),"",ROUND(H7*I7/1000000,2)) | K7: =IF(J7="","",ROUND(J7*Annahmen!$B$7/Annahmen!$B$6,0)*Annahmen!$B$6) | M7: =IF(OR(G7="",L7=""),"",1-L7/G7) | N7: 2 | O7: 4 | P7: =N7*Annahmen!$B$9 | Q7: =O7*Annahmen!$B$9 | R7: =HYPERLINK(Annahmen!$B$11&"#artikel/tw-21","Stück öffnen") | S7: Formel Fläche × CHF/m² (Annahme)
A8: TW 22 | B8: Neue Glasplatten | C8: Strukturglas-Platte mit feiner Textur | D8: 760 × 2030 mm · 8 mm Glas | E8: verfügbar | F8: Preis auf Anfrage | H8: 760 | I8: 2030 | J8: =IF(OR(H8="",I8=""),"",ROUND(H8*I8/1000000,2)) | K8: =IF(J8="","",ROUND(J8*Annahmen!$B$7/Annahmen!$B$6,0)*Annahmen!$B$6) | M8: =IF(OR(G8="",L8=""),"",1-L8/G8) | N8: 2 | O8: 4 | P8: =N8*Annahmen!$B$9 | Q8: =O8*Annahmen!$B$9 | R8: =HYPERLINK(Annahmen!$B$11&"#artikel/tw-22","Stück öffnen") | S8: Formel Fläche × CHF/m² (Annahme)
A9: TW 24 | B9: Neue Glasplatten | C9: Strukturglas-Platte mit Meeresmotiv | D9: 805 × 1975 mm · 8 mm Glas | E9: verfügbar | F9: Preis auf Anfrage | H9: 805 | I9: 1975 | J9: =IF(OR(H9="",I9=""),"",ROUND(H9*I9/1000000,2)) | K9: =IF(J9="","",ROUND(J9*Annahmen!$B$7/Annahmen!$B$6,0)*Annahmen!$B$6) | M9: =IF(OR(G9="",L9=""),"",1-L9/G9) | N9: 2 | O9: 4 | P9: =N9*Annahmen!$B$9 | Q9: =O9*Annahmen!$B$9 | R9: =HYPERLINK(Annahmen!$B$11&"#artikel/tw-24","Stück öffnen") | S9: Formel Fläche × CHF/m² (Annahme)
A10: TW 25 | B10: Neue Glasplatten | C10: Strukturglas-Platte mit Felsstruktur | D10: 800 × 1950 mm · 10 mm Glas | E10: verfügbar | F10: Preis auf Anfrage | H10: 800 | I10: 1950 | J10: =IF(OR(H10="",I10=""),"",ROUND(H10*I10/1000000,2)) | K10: =IF(J10="","",ROUND(J10*Annahmen!$B$8/Annahmen!$B$6,0)*Annahmen!$B$6) | M10: =IF(OR(G10="",L10=""),"",1-L10/G10) | N10: 2 | O10: 4 | P10: =N10*Annahmen!$B$9 | Q10: =O10*Annahmen!$B$9 | R10: =HYPERLINK(Annahmen!$B$11&"#artikel/tw-25","Stück öffnen") | S10: Formel Fläche × CHF/m² (Annahme)
A11: TW 26 | B11: Neue Glasplatten | C11: Strukturglas-Platte mit Delfinen | D11: 605 × 1958 mm · 8 mm Glas | E11: verfügbar | F11: Preis auf Anfrage | H11: 605 | I11: 1958 | J11: =IF(OR(H11="",I11=""),"",ROUND(H11*I11/1000000,2)) | K11: =IF(J11="","",ROUND(J11*Annahmen!$B$7/Annahmen!$B$6,0)*Annahmen!$B$6) | M11: =IF(OR(G11="",L11=""),"",1-L11/G11) | N11: 2 | O11: 4 | P11: =N11*Annahmen!$B$9 | Q11: =O11*Annahmen!$B$9 | R11: =HYPERLINK(Annahmen!$B$11&"#artikel/tw-26","Stück öffnen") | S11: Formel Fläche × CHF/m² (Annahme)
A12: TW 28 | B12: Neue Glasplatten | C12: Schmale Strukturglas-Platte | D12: 530 × 2005 mm · 10 mm Glas | E12: verfügbar | F12: Preis auf Anfrage | H12: 530 | I12: 2005 | J12: =IF(OR(H12="",I12=""),"",ROUND(H12*I12/1000000,2)) | K12: =IF(J12="","",ROUND(J12*Annahmen!$B$8/Annahmen!$B$6,0)*Annahmen!$B$6) | M12: =IF(OR(G12="",L12=""),"",1-L12/G12) | N12: 2 | O12: 4 | P12: =N12*Annahmen!$B$9 | Q12: =O12*Annahmen!$B$9 | R12: =HYPERLINK(Annahmen!$B$11&"#artikel/tw-28","Stück öffnen") | S12: Formel Fläche × CHF/m² (Annahme)
A13: TW 29 | B13: Neue Glasplatten | C13: Schmale Strukturglas-Platte | D13: 505 × 1970 mm · 8 mm Glas | E13: verfügbar | F13: Preis auf Anfrage | H13: 505 | I13: 1970 | J13: =IF(OR(H13="",I13=""),"",ROUND(H13*I13/1000000,2)) | K13: =IF(J13="","",ROUND(J13*Annahmen!$B$7/Annahmen!$B$6,0)*Annahmen!$B$6) | M13: =IF(OR(G13="",L13=""),"",1-L13/G13) | N13: 2 | O13: 4 | P13: =N13*Annahmen!$B$9 | Q13: =O13*Annahmen!$B$9 | R13: =HYPERLINK(Annahmen!$B$11&"#artikel/tw-29","Stück öffnen") | S13: Formel Fläche × CHF/m² (Annahme)
A14: TW 31 | B14: Neue Glasplatten | C14: Strukturglas-Platte mit Felsstruktur | D14: 1005 × 1955 mm · 10 mm Glas | E14: verfügbar | F14: Preis auf Anfrage | H14: 1005 | I14: 1955 | J14: =IF(OR(H14="",I14=""),"",ROUND(H14*I14/1000000,2)) | K14: =IF(J14="","",ROUND(J14*Annahmen!$B$8/Annahmen!$B$6,0)*Annahmen!$B$6) | M14: =IF(OR(G14="",L14=""),"",1-L14/G14) | N14: 2 | O14: 4 | P14: =N14*Annahmen!$B$9 | Q14: =O14*Annahmen!$B$9 | R14: =HYPERLINK(Annahmen!$B$11&"#artikel/tw-31","Stück öffnen") | S14: Formel Fläche × CHF/m² (Annahme)
A15: TW 32 | B15: Neue Glasplatten | C15: Strukturglas-Platte mit kräftiger Struktur | D15: 1035 × 2100 mm · 10 mm Glas | E15: verfügbar | F15: Preis auf Anfrage | H15: 1035 | I15: 2100 | J15: =IF(OR(H15="",I15=""),"",ROUND(H15*I15/1000000,2)) | K15: =IF(J15="","",ROUND(J15*Annahmen!$B$8/Annahmen!$B$6,0)*Annahmen!$B$6) | M15: =IF(OR(G15="",L15=""),"",1-L15/G15) | N15: 2 | O15: 4 | P15: =N15*Annahmen!$B$9 | Q15: =O15*Annahmen!$B$9 | R15: =HYPERLINK(Annahmen!$B$11&"#artikel/tw-32","Stück öffnen") | S15: Formel Fläche × CHF/m² (Annahme)
A16: TW 33 | B16: Neue Glasplatten | C16: Strukturglas-Platte mit Reliefstruktur | D16: 1050 × 2000 mm · 10 mm Glas | E16: verfügbar | F16: Preis auf Anfrage | H16: 1050 | I16: 2000 | J16: =IF(OR(H16="",I16=""),"",ROUND(H16*I16/1000000,2)) | K16: =IF(J16="","",ROUND(J16*Annahmen!$B$8/Annahmen!$B$6,0)*Annahmen!$B$6) | M16: =IF(OR(G16="",L16=""),"",1-L16/G16) | N16: 2 | O16: 4 | P16: =N16*Annahmen!$B$9 | Q16: =O16*Annahmen!$B$9 | R16: =HYPERLINK(Annahmen!$B$11&"#artikel/tw-33","Stück öffnen") | S16: Formel Fläche × CHF/m² (Annahme)
A17: TW 34 | B17: Neue Glasplatten | C17: Strukturglas-Platte mit Felsstruktur | D17: 1100 × 2000 mm · 10 mm Glas | E17: verfügbar | F17: Preis auf Anfrage | H17: 1100 | I17: 2000 | J17: =IF(OR(H17="",I17=""),"",ROUND(H17*I17/1000000,2)) | K17: =IF(J17="","",ROUND(J17*Annahmen!$B$8/Annahmen!$B$6,0)*Annahmen!$B$6) | M17: =IF(OR(G17="",L17=""),"",1-L17/G17) | N17: 2 | O17: 4 | P17: =N17*Annahmen!$B$9 | Q17: =O17*Annahmen!$B$9 | R17: =HYPERLINK(Annahmen!$B$11&"#artikel/tw-34","Stück öffnen") | S17: Formel Fläche × CHF/m² (Annahme)
A18: TW 35 | B18: Neue Glasplatten | C18: Breite Strukturglas-Platte mit geschwungener Kante | D18: 1250 × 1950 mm · 10 mm Glas | E18: verfügbar | F18: Preis auf Anfrage | H18: 1250 | I18: 1950 | J18: =IF(OR(H18="",I18=""),"",ROUND(H18*I18/1000000,2)) | K18: =IF(J18="","",ROUND(J18*Annahmen!$B$8/Annahmen!$B$6,0)*Annahmen!$B$6) | M18: =IF(OR(G18="",L18=""),"",1-L18/G18) | N18: 2 | O18: 4 | P18: =N18*Annahmen!$B$9 | Q18: =O18*Annahmen!$B$9 | R18: =HYPERLINK(Annahmen!$B$11&"#artikel/tw-35","Stück öffnen") | S18: Formel Fläche × CHF/m² (Annahme)
A19: TW 36 | B19: Neue Glasplatten | C19: Strukturglas-Platte mit Linienstruktur | D19: 1200 × 2000 mm · 8 mm Glas | E19: verfügbar | F19: Preis auf Anfrage | H19: 1200 | I19: 2000 | J19: =IF(OR(H19="",I19=""),"",ROUND(H19*I19/1000000,2)) | K19: =IF(J19="","",ROUND(J19*Annahmen!$B$7/Annahmen!$B$6,0)*Annahmen!$B$6) | M19: =IF(OR(G19="",L19=""),"",1-L19/G19) | N19: 2 | O19: 4 | P19: =N19*Annahmen!$B$9 | Q19: =O19*Annahmen!$B$9 | R19: =HYPERLINK(Annahmen!$B$11&"#artikel/tw-36","Stück öffnen") | S19: Formel Fläche × CHF/m² (Annahme)
A20: TW 37 | B20: Neue Glasplatten | C20: Strukturglas-Platte mit feiner Linienstruktur | D20: Masse auf Anfrage · 8 mm Glas | E20: verfügbar | F20: Preis auf Anfrage | J20: =IF(OR(H20="",I20=""),"",ROUND(H20*I20/1000000,2)) | K20: =IF(J20="","",ROUND(J20*Annahmen!$B$7/Annahmen!$B$6,0)*Annahmen!$B$6) | M20: =IF(OR(G20="",L20=""),"",1-L20/G20) | N20: 2 | O20: 4 | P20: =N20*Annahmen!$B$9 | Q20: =O20*Annahmen!$B$9 | R20: =HYPERLINK(Annahmen!$B$11&"#artikel/tw-37","Stück öffnen") | S20: Masse fehlen – Preis manuell
A21: TW 38 | B21: Neue Glasplatten | C21: Strukturglas-Platte mit Reliefstruktur | D21: Masse auf Anfrage · 10 mm Glas | E21: verfügbar | F21: Preis auf Anfrage | J21: =IF(OR(H21="",I21=""),"",ROUND(H21*I21/1000000,2)) | K21: =IF(J21="","",ROUND(J21*Annahmen!$B$8/Annahmen!$B$6,0)*Annahmen!$B$6) | M21: =IF(OR(G21="",L21=""),"",1-L21/G21) | N21: 2 | O21: 4 | P21: =N21*Annahmen!$B$9 | Q21: =O21*Annahmen!$B$9 | R21: =HYPERLINK(Annahmen!$B$11&"#artikel/tw-38","Stück öffnen") | S21: Masse fehlen – Preis manuell
A22: BA-06 | B22: Glaswaschtische | C22: LED-Glaswaschtisch 160 cm mit Holz-Unterschrank | D22: 160 cm · zwei Becken · LED-Beleuchtung · Unterschrank Holzdekor · ohne Armaturen | E22: verfügbar | F22: Katalogpreis 05/2025 | G22: 1920 | J22: =IF(OR(H22="",I22=""),"",ROUND(H22*I22/1000000,2)) | K22: =IF(G22="","",ROUND(G22*(1-IF(G22<=300,Annahmen!$B$2,IF(G22<=1000,Annahmen!$B$3,IF(G22<=3000,Annahmen!$B$4,Annahmen!$B$5))))/Annahmen!$B$6,0)*Annahmen!$B$6) | M22: =IF(OR(G22="",L22=""),"",1-L22/G22) | N22: 3 | O22: 4 | P22: =N22*Annahmen!$B$9 | Q22: =O22*Annahmen!$B$9 | R22: =HYPERLINK(Annahmen!$B$11&"#artikel/ba-06-led-glass-washbasin-160cm","Stück öffnen")
A23: BA-W | B23: Glaswaschtische | C23: Weiss lackierter Glaswaschtisch 76 × 51 cm | D23: 76 × 51 cm · weiss lackiert · Edelstahlkonsolen · ohne Armaturen | E23: verfügbar | F23: Katalogpreis 05/2025 | G23: 800 | J23: =IF(OR(H23="",I23=""),"",ROUND(H23*I23/1000000,2)) | K23: =IF(G23="","",ROUND(G23*(1-IF(G23<=300,Annahmen!$B$2,IF(G23<=1000,Annahmen!$B$3,IF(G23<=3000,Annahmen!$B$4,Annahmen!$B$5))))/Annahmen!$B$6,0)*Annahmen!$B$6) | M23: =IF(OR(G23="",L23=""),"",1-L23/G23) | N23: 1.5 | O23: 2.5 | P23: =N23*Annahmen!$B$9 | Q23: =O23*Annahmen!$B$9 | R23: =HYPERLINK(Annahmen!$B$11&"#artikel/ba-w-white-lacquered-washbasin","Stück öffnen")
A24: BA-05 | B24: Glaswaschtische | C24: LED-Glaswaschtisch 99,5 × 52,5 cm mit Steinoptik-Unterschrank | D24: 99,5 × 52,5 cm · LED-Beleuchtung · Unterschrank Steinoptik · ohne Armaturen | E24: verfügbar | F24: Katalogpreis 05/2025 | G24: 1140 | J24: =IF(OR(H24="",I24=""),"",ROUND(H24*I24/1000000,2)) | K24: =IF(G24="","",ROUND(G24*(1-IF(G24<=300,Annahmen!$B$2,IF(G24<=1000,Annahmen!$B$3,IF(G24<=3000,Annahmen!$B$4,Annahmen!$B$5))))/Annahmen!$B$6,0)*Annahmen!$B$6) | M24: =IF(OR(G24="",L24=""),"",1-L24/G24) | N24: 3 | O24: 4 | P24: =N24*Annahmen!$B$9 | Q24: =O24*Annahmen!$B$9 | R24: =HYPERLINK(Annahmen!$B$11&"#artikel/ba-05-led-glass-washbasin-99cm","Stück öffnen")
A25: BA-03 | B25: Glaswaschtische | C25: LED-Glaswaschtisch 80 cm mit Unterschrank | D25: 80 cm · LED-Beleuchtung · Unterschrank Steinoptik · ohne Armaturen | E25: verfügbar | F25: Katalogpreis 05/2025 | G25: 850 | J25: =IF(OR(H25="",I25=""),"",ROUND(H25*I25/1000000,2)) | K25: =IF(G25="","",ROUND(G25*(1-IF(G25<=300,Annahmen!$B$2,IF(G25<=1000,Annahmen!$B$3,IF(G25<=3000,Annahmen!$B$4,Annahmen!$B$5))))/Annahmen!$B$6,0)*Annahmen!$B$6) | M25: =IF(OR(G25="",L25=""),"",1-L25/G25) | N25: 3 | O25: 4 | P25: =N25*Annahmen!$B$9 | Q25: =O25*Annahmen!$B$9 | R25: =HYPERLINK(Annahmen!$B$11&"#artikel/ba-03-led-glass-washbasin-80cm","Stück öffnen")
A26: BA-M4 | B26: Glaswaschtische | C26: Glasschüssel-Set Modell 4 auf roter Glasplatte | D26: Schüssel schwarz-gold · rote Glasabdeckung · Konsolen · ohne Armatur | E26: verfügbar | F26: Katalogpreis 05/2025 | G26: 650 | J26: =IF(OR(H26="",I26=""),"",ROUND(H26*I26/1000000,2)) | K26: =IF(G26="","",ROUND(G26*(1-IF(G26<=300,Annahmen!$B$2,IF(G26<=1000,Annahmen!$B$3,IF(G26<=3000,Annahmen!$B$4,Annahmen!$B$5))))/Annahmen!$B$6,0)*Annahmen!$B$6) | M26: =IF(OR(G26="",L26=""),"",1-L26/G26) | N26: 1.5 | O26: 2.5 | P26: =N26*Annahmen!$B$9 | Q26: =O26*Annahmen!$B$9 | R26: =HYPERLINK(Annahmen!$B$11&"#artikel/ba-m4-glass-bowl-set-model-4","Stück öffnen")
A27: BA-RD | B27: Duschen | C27: Runddusche mit Glasboden und Glasdecke | D27: H 206 cm · B 130/100 cm · mit Boden und Decke · Komplettset | E27: verfügbar | F27: Aktionspreis Nov 2026 (bestätigt) | G27: 4000 | J27: =IF(OR(H27="",I27=""),"",ROUND(H27*I27/1000000,2)) | K27: =G27 | M27: =IF(OR(G27="",L27=""),"",1-L27/G27) | N27: 5 | O27: 8 | P27: =N27*Annahmen!$B$9 | Q27: =O27*Annahmen!$B$9 | R27: =HYPERLINK(Annahmen!$B$11&"#artikel/ba-rd-round-shower","Stück öffnen") | S27: Aktionspreis bereits bestätigt
A28: BA-ED | B28: Duschen | C28: Eckdusche 100 × 120 cm mit Schiebetüren | D28: 100 × 120 cm, H 200 cm · 2 Fixgläser, 2 Schiebegläser · inkl. Set Eckschiebetüre, Beschläge, Schienen, Griff, Dichtungen | E28: verfügbar | F28: Katalogpreis 05/2025 | G28: 3000 | J28: =IF(OR(H28="",I28=""),"",ROUND(H28*I28/1000000,2)) | K28: =IF(G28="","",ROUND(G28*(1-IF(G28<=300,Annahmen!$B$2,IF(G28<=1000,Annahmen!$B$3,IF(G28<=3000,Annahmen!$B$4,Annahmen!$B$5))))/Annahmen!$B$6,0)*Annahmen!$B$6) | M28: =IF(OR(G28="",L28=""),"",1-L28/G28) | N28: 5 | O28: 8 | P28: =N28*Annahmen!$B$9 | Q28: =O28*Annahmen!$B$9 | R28: =HYPERLINK(Annahmen!$B$11&"#artikel/ba-ed-corner-sliding-shower","Stück öffnen")
A29: BA-FD | B29: Duschen | C29: Faltentür für Nischendusche 82 × 204 cm | D29: 82,3 × 204 cm · mit Beschlägen · Rückwände und Boden auf Anfrage | E29: verfügbar | F29: Katalogpreis 05/2025 | G29: 1500 | J29: =IF(OR(H29="",I29=""),"",ROUND(H29*I29/1000000,2)) | K29: =IF(G29="","",ROUND(G29*(1-IF(G29<=300,Annahmen!$B$2,IF(G29<=1000,Annahmen!$B$3,IF(G29<=3000,Annahmen!$B$4,Annahmen!$B$5))))/Annahmen!$B$6,0)*Annahmen!$B$6) | M29: =IF(OR(G29="",L29=""),"",1-L29/G29) | N29: 5 | O29: 8 | P29: =N29*Annahmen!$B$9 | Q29: =O29*Annahmen!$B$9 | R29: =HYPERLINK(Annahmen!$B$11&"#artikel/ba-fd-folding-shower-door","Stück öffnen")
A30: BA-SD | B30: Duschen | C30: Dusch-Schiebetüre 100 × 200 cm | D30: 100 × 200 cm · mit Beschlägen · Rückwände auf Anfrage | E30: verfügbar | F30: Katalogpreis 05/2025 | G30: 1500 | J30: =IF(OR(H30="",I30=""),"",ROUND(H30*I30/1000000,2)) | K30: =IF(G30="","",ROUND(G30*(1-IF(G30<=300,Annahmen!$B$2,IF(G30<=1000,Annahmen!$B$3,IF(G30<=3000,Annahmen!$B$4,Annahmen!$B$5))))/Annahmen!$B$6,0)*Annahmen!$B$6) | M30: =IF(OR(G30="",L30=""),"",1-L30/G30) | N30: 5 | O30: 8 | P30: =N30*Annahmen!$B$9 | Q30: =O30*Annahmen!$B$9 | R30: =HYPERLINK(Annahmen!$B$11&"#artikel/ba-sd-sliding-shower-door","Stück öffnen")
A31: BA-D | B31: Glastüren | C31: Glas-Drehtüre mit Delfinrelief, ESG | D31: 80,5 × 218 cm · ESG · inkl. Beschläge und Griff | E31: verkauft | F31: Katalogpreis 05/2025 | G31: 1400 | J31: =IF(OR(H31="",I31=""),"",ROUND(H31*I31/1000000,2)) | M31: =IF(OR(G31="",L31=""),"",1-L31/G31) | N31: 2 | O31: 3 | P31: =N31*Annahmen!$B$9 | Q31: =O31*Annahmen!$B$9 | R31: =HYPERLINK(Annahmen!$B$11&"#artikel/ba-d-dolphin-relief-glass-door","Stück öffnen") | S31: Verkauft – nur Dokumentation
A32: BA-P | B32: Glastüren | C32: Glas-Drehtüre mit Palmenrelief, ESG | D32: 84 × 201,5 cm · ESG · inkl. Schiene, Beschläge und Griff | E32: verfügbar | F32: Katalogpreis 05/2025 | G32: 1200 | J32: =IF(OR(H32="",I32=""),"",ROUND(H32*I32/1000000,2)) | K32: =IF(G32="","",ROUND(G32*(1-IF(G32<=300,Annahmen!$B$2,IF(G32<=1000,Annahmen!$B$3,IF(G32<=3000,Annahmen!$B$4,Annahmen!$B$5))))/Annahmen!$B$6,0)*Annahmen!$B$6) | M32: =IF(OR(G32="",L32=""),"",1-L32/G32) | N32: 2 | O32: 3 | P32: =N32*Annahmen!$B$9 | Q32: =O32*Annahmen!$B$9 | R32: =HYPERLINK(Annahmen!$B$11&"#artikel/ba-p-palm-relief-glass-door","Stück öffnen")
A33: LA 04 | B33: Glaswaschtische | C33: Glaswaschtisch 130 × 70 cm mit ovalem Becken | D33: 130 × 70 cm · Strukturglas klar · ovales Becken | E33: verfügbar | F33: Katalogpreis 05/2025 | G33: 1500 | J33: =IF(OR(H33="",I33=""),"",ROUND(H33*I33/1000000,2)) | K33: =IF(G33="","",ROUND(G33*(1-IF(G33<=300,Annahmen!$B$2,IF(G33<=1000,Annahmen!$B$3,IF(G33<=3000,Annahmen!$B$4,Annahmen!$B$5))))/Annahmen!$B$6,0)*Annahmen!$B$6) | M33: =IF(OR(G33="",L33=""),"",1-L33/G33) | N33: 1.5 | O33: 2.5 | P33: =N33*Annahmen!$B$9 | Q33: =O33*Annahmen!$B$9 | R33: =HYPERLINK(Annahmen!$B$11&"#artikel/la-04-glass-washbasin","Stück öffnen")
A34: LA 11 | B34: Glaswaschtische | C34: Glaswaschtisch 145 × 65 cm, Weiss | D34: 145 × 65 cm · weiss | E34: verfügbar | F34: Katalogpreis 05/2025 | G34: 800 | J34: =IF(OR(H34="",I34=""),"",ROUND(H34*I34/1000000,2)) | K34: =IF(G34="","",ROUND(G34*(1-IF(G34<=300,Annahmen!$B$2,IF(G34<=1000,Annahmen!$B$3,IF(G34<=3000,Annahmen!$B$4,Annahmen!$B$5))))/Annahmen!$B$6,0)*Annahmen!$B$6) | M34: =IF(OR(G34="",L34=""),"",1-L34/G34) | N34: 1.5 | O34: 2.5 | P34: =N34*Annahmen!$B$9 | Q34: =O34*Annahmen!$B$9 | R34: =HYPERLINK(Annahmen!$B$11&"#artikel/la-11-glass-washbasin","Stück öffnen")
A35: LA 21 | B35: Glaswaschtische | C35: Geschwungener Glaswaschtisch 122 × 40 cm | D35: 122 × 40 cm · geschwungen · Strukturglas klar | E35: verfügbar | F35: Katalogpreis 05/2025 | G35: 800 | J35: =IF(OR(H35="",I35=""),"",ROUND(H35*I35/1000000,2)) | K35: =IF(G35="","",ROUND(G35*(1-IF(G35<=300,Annahmen!$B$2,IF(G35<=1000,Annahmen!$B$3,IF(G35<=3000,Annahmen!$B$4,Annahmen!$B$5))))/Annahmen!$B$6,0)*Annahmen!$B$6) | M35: =IF(OR(G35="",L35=""),"",1-L35/G35) | N35: 1.5 | O35: 2.5 | P35: =N35*Annahmen!$B$9 | Q35: =O35*Annahmen!$B$9 | R35: =HYPERLINK(Annahmen!$B$11&"#artikel/la-21-glass-washbasin","Stück öffnen")
A36: LA 23 | B36: Glaswaschtische | C36: Glaswaschtisch 80 × 56 cm, Kobaltblau | D36: 80 × 56 cm · kobaltblau | E36: verfügbar | F36: Katalogpreis 05/2025 | G36: 300 | J36: =IF(OR(H36="",I36=""),"",ROUND(H36*I36/1000000,2)) | K36: =IF(G36="","",ROUND(G36*(1-IF(G36<=300,Annahmen!$B$2,IF(G36<=1000,Annahmen!$B$3,IF(G36<=3000,Annahmen!$B$4,Annahmen!$B$5))))/Annahmen!$B$6,0)*Annahmen!$B$6) | M36: =IF(OR(G36="",L36=""),"",1-L36/G36) | N36: 1.5 | O36: 2.5 | P36: =N36*Annahmen!$B$9 | Q36: =O36*Annahmen!$B$9 | R36: =HYPERLINK(Annahmen!$B$11&"#artikel/la-23-glass-washbasin","Stück öffnen")
A37: LA 26 | B37: Glaswaschtische | C37: Doppelwaschtisch 170 × 65 cm, Gelb, mit Unterschrank | D37: 170 × 65 cm · zwei Becken · gelb · mit Unterschrank | E37: verfügbar | F37: Katalogpreis 05/2025 | G37: 1500 | J37: =IF(OR(H37="",I37=""),"",ROUND(H37*I37/1000000,2)) | K37: =IF(G37="","",ROUND(G37*(1-IF(G37<=300,Annahmen!$B$2,IF(G37<=1000,Annahmen!$B$3,IF(G37<=3000,Annahmen!$B$4,Annahmen!$B$5))))/Annahmen!$B$6,0)*Annahmen!$B$6) | M37: =IF(OR(G37="",L37=""),"",1-L37/G37) | N37: 3 | O37: 4 | P37: =N37*Annahmen!$B$9 | Q37: =O37*Annahmen!$B$9 | R37: =HYPERLINK(Annahmen!$B$11&"#artikel/la-26-glass-washbasin","Stück öffnen")
A38: LA 28 | B38: Glaswaschtische | C38: Glaswaschtisch 200 × 65 cm auf Holzsockel | D38: 200 × 65 cm · zwei Becken · Holzsockel | E38: verfügbar | F38: Katalogpreis 05/2025 | G38: 2000 | J38: =IF(OR(H38="",I38=""),"",ROUND(H38*I38/1000000,2)) | K38: =IF(G38="","",ROUND(G38*(1-IF(G38<=300,Annahmen!$B$2,IF(G38<=1000,Annahmen!$B$3,IF(G38<=3000,Annahmen!$B$4,Annahmen!$B$5))))/Annahmen!$B$6,0)*Annahmen!$B$6) | M38: =IF(OR(G38="",L38=""),"",1-L38/G38) | N38: 3 | O38: 4 | P38: =N38*Annahmen!$B$9 | Q38: =O38*Annahmen!$B$9 | R38: =HYPERLINK(Annahmen!$B$11&"#artikel/la-28-glass-washbasin","Stück öffnen")
A39: LA 30 | B39: Glaswaschtische | C39: Glaswaschtisch 96 × 56 cm mit Altholz-Unterschrank | D39: 96 × 56 cm · Unterschrank Altholz | E39: verfügbar | F39: Katalogpreis 05/2025 | G39: 1000 | J39: =IF(OR(H39="",I39=""),"",ROUND(H39*I39/1000000,2)) | K39: =IF(G39="","",ROUND(G39*(1-IF(G39<=300,Annahmen!$B$2,IF(G39<=1000,Annahmen!$B$3,IF(G39<=3000,Annahmen!$B$4,Annahmen!$B$5))))/Annahmen!$B$6,0)*Annahmen!$B$6) | M39: =IF(OR(G39="",L39=""),"",1-L39/G39) | N39: 3 | O39: 4 | P39: =N39*Annahmen!$B$9 | Q39: =O39*Annahmen!$B$9 | R39: =HYPERLINK(Annahmen!$B$11&"#artikel/la-30-glass-washbasin","Stück öffnen")
A40: LA 34 | B40: Glaswaschtische | C40: Glaswaschtisch 180 × 65 cm mit zwei Becken | D40: 180 × 65 cm · zwei Becken · ohne Unterschrank | E40: verfügbar | F40: Katalogpreis 05/2025 | G40: 3050 | J40: =IF(OR(H40="",I40=""),"",ROUND(H40*I40/1000000,2)) | K40: =IF(G40="","",ROUND(G40*(1-IF(G40<=300,Annahmen!$B$2,IF(G40<=1000,Annahmen!$B$3,IF(G40<=3000,Annahmen!$B$4,Annahmen!$B$5))))/Annahmen!$B$6,0)*Annahmen!$B$6) | M40: =IF(OR(G40="",L40=""),"",1-L40/G40) | N40: 3 | O40: 4 | P40: =N40*Annahmen!$B$9 | Q40: =O40*Annahmen!$B$9 | R40: =HYPERLINK(Annahmen!$B$11&"#artikel/la-34-glass-washbasin","Stück öffnen")
...

Sheet Annahmen
A1: Annahme | B1: Wert | C1: Erläuterung
A2: Rabatt bis CHF 300 | B2: 0 | C2: Kleinteile: Preis bleibt. Problem ist Sichtbarkeit, nicht Preis.
A3: Rabatt CHF 301–1000 | B3: 0.2 | C3: Vorschlag. Anpassen und Spalte "Vorschlag" rechnet neu.
A4: Rabatt CHF 1001–3000 | B4: 0.25 | C4: Vorschlag.
A5: Rabatt über CHF 3000 | B5: 0.3 | C5: Vorschlag. Grosse Stücke stehen am längsten.
A6: Rundung auf CHF | B6: 10 | C6: Vorschlagspreis wird auf diesen Betrag gerundet.
A7: Glasplatten 8 mm, CHF pro m² | B7: 350 | C7: Annahme für Strukturglas dekorativ. Bitte vom Chef bestätigen.
A8: Glasplatten 10 mm, CHF pro m² | B8: 420 | C8: Annahme. Bitte vom Chef bestätigen.
A9: Montage CHF pro Stunde | B9: 220 | C9: Team mit 2 Personen, inkl. Werkzeug. Vorgabe.
A10: Lieferung gratis ab Warenwert CHF | B10: 3000 | C10: Nur Lieferung ohne Montage, Zonen A–C.
A11: Basis-URL Katalog | B11: https://higorvibecode.github.io/aktioncrea/ | C11: Für die Links pro Stück. Anpassen, wenn die Seite unter einer anderen Adresse läuft.
A13: Gelbe Zellen sind Entscheidungen. Alles andere rechnet automatisch.

Sheet Lieferung & Montage
A1: Zone | B1: Distanz ab Werk (Strasse) | C1: Beispielorte | D1: Lieferung ohne Montage CHF | E1: Anfahrt bei Montage CHF | F1: Regel
A2: A | B2: bis 15 km | C2: Interlaken, Matten, Wilderswil, Bönigen, Ringgenberg, Beatenberg | D2: 90 | E2: 0 | F2: Lieferung gratis ab CHF 3000 Warenwert
A3: B | B3: bis 40 km | C3: Thun, Spiez, Brienz, Meiringen, Grindelwald, Lauterbrunnen, Frutigen | D3: 160 | E3: 120 | F3: Lieferung gratis ab CHF 3000 Warenwert
A4: C | B4: bis 80 km | C4: Bern, Burgdorf, Luzern, Zweisimmen, Gstaad | D4: 260 | E4: 240 | F4: Lieferung gratis ab CHF 3000 Warenwert
A5: D | B5: über 80 km | C5: Zürich, Basel, Romandie, Wallis | D5: Offerte | E5: Offerte | F5: Individuell offerieren
A7: Grundsätze (Vorschlag)
A8: Abholung ab Werk Unterseen: kostenlos.
A9: Lieferung ohne Montage: Pauschale pro Auftrag nach Zone. Gratis ab CHF 3000 Warenwert in den Zonen A–C.
A10: Lieferung mit Montage: Lieferung immer inbegriffen. Anfahrtspauschale nach Zone plus Montagestunden × CHF 220.
A11: Kleines Zubehör (Siphon, Konsolen, Tablarträger, Handtuchhalter): Postversand CHF 15.
A12: Montagezeit: Fenster min–max pro Stück, siehe Blatt "Montagezeiten". Auf der Website wird die Spanne als Richtpreis gezeigt.
A13: Sanitär- und Elektroanschlüsse: durch den Installateur des Kunden oder nach Absprache. Steht so auf der Website.
A14: Alle Beträge sind Richtpreise. Crea-Glass bestätigt vor Auftrag. Die Website sagt das bei jedem Preis.
A16: So wird das in der Schweiz üblicherweise gehandhabt (Erfahrungswerte, nicht recherchiert – Netzwerkzugriff war in dieser Sitzung gesperrt)
A17: Handwerksbetriebe verrechnen Anfahrt als Pauschale pro Zone oder als Fahrzeit zum Stundensatz. Zonenpauschalen sind für Kunden verständlicher.
A18: Sanitär-Ausstellungen liefern grössere Stücke meist mit Pauschale pro Auftrag; viele verzichten auf die Liefergebühr ab einem Warenwert (häufig CHF 2000–5000).
A19: Montage-Stundensätze für ein Zweierteam im Glaserhandwerk liegen in der Region typischerweise bei CHF 180–260. CHF 220 liegt im Rahmen.
A20: Empfehlung: Gratislieferung nur ohne Montage (als Kaufanreiz) und nur bis Zone C. Bei Montage ist die Lieferung ohnehin inbegriffen, dort braucht es keinen Zusatzrabatt.

Sheet Montagezeiten
A1: Produktgruppe | B1: Stunden min | C1: Stunden max | D1: CHF min | E1: CHF max | F1: Umfang | G1: Nicht enthalten
A2: Glaswaschtisch ohne Möbel | B2: 1.5 | C2: 2.5 | D2: =B2*Annahmen!$B$9 | E2: =C2*Annahmen!$B$9 | F2: Konsolen setzen, Waschtisch montieren, ausrichten | G2: Wasseranschluss (Sanitär)
A3: Glaswaschtisch mit Möbel / Komplettset | B3: 3 | C3: 4 | D3: =B3*Annahmen!$B$9 | E3: =C3*Annahmen!$B$9 | F3: Möbel stellen, Waschtisch montieren, LED anschliessen | G3: Wasseranschluss (Sanitär), Stromzuleitung
A4: Dusche komplett | B4: 5 | C4: 8 | D4: =B4*Annahmen!$B$9 | E4: =C4*Annahmen!$B$9 | F4: Rückwände, Trennwände, Türen, Beschläge, Abdichtung Glas | G4: Armaturen, Bodenabdichtung, Sanitär
A5: Duschtüre (Falt/Schiebe) | B5: 3 | C5: 4 | D5: =B5*Annahmen!$B$9 | E5: =C5*Annahmen!$B$9 | F5: Profile, Türe, Beschläge, Dichtungen | G5: Rückwände, Sanitär
A6: Glastüre | B6: 2 | C6: 3 | D6: =B6*Annahmen!$B$9 | E6: =C6*Annahmen!$B$9 | F6: Beschläge, Türe einhängen, einstellen | G6: Zarge/Anpassung Mauerwerk
A7: Glastrennwand | B7: 2 | C7: 4 | D7: =B7*Annahmen!$B$9 | E7: =C7*Annahmen!$B$9 | F7: Profile oder Punkthalter, Glas setzen, abdichten | G7: Bauliche Anpassungen
A8: Neue Glasplatte (Einbau nach Aufmass) | B8: 2 | C8: 4 | D8: =B8*Annahmen!$B$9 | E8: =C8*Annahmen!$B$9 | F8: Aufmass, Halterung, Glas setzen | G8: Beschläge je nach Einsatz
A9: Spiegel ohne LED | B9: 1 | C9: 1.5 | D9: =B9*Annahmen!$B$9 | E9: =C9*Annahmen!$B$9 | F9: Befestigung, ausrichten
A10: Spiegel mit LED | B10: 1.5 | C10: 2 | D10: =B10*Annahmen!$B$9 | E10: =C10*Annahmen!$B$9 | F10: Befestigung, Anschluss an vorhandene Zuleitung | G10: Stromzuleitung (Elektriker)
A11: Glasbild | B11: 0.5 | C11: 1 | D11: =B11*Annahmen!$B$9 | E11: =C11*Annahmen!$B$9 | F11: Aufhängung, ausrichten | G11: Stromzuleitung bei LED
A12: Tisch / Möbel | B12: 1 | C12: 2 | D12: =B12*Annahmen!$B$9 | E12: =C12*Annahmen!$B$9 | F12: Lieferung, aufstellen, ausrichten
A13: Bartheke | B13: 2 | C13: 3 | D13: =B13*Annahmen!$B$9 | E13: =C13*Annahmen!$B$9 | F13: Aufstellen, Glasplatte montieren
A14: Zubehör | B14: 0.5 | C14: 1 | D14: =B14*Annahmen!$B$9 | E14: =C14*Annahmen!$B$9 | F14: Montage an Wand oder Möbel
A16: Stunden sind Schätzungen für ein Zweierteam. Bitte mit der Montage abgleichen. Die Website nutzt dieselben Werte (services.js).
